[01;31m!! [D/T] The group 'groupeA' doesn't exist.[0;0m
>>> [01;31mException[0;0m: [01;36m<class 'licorn.foundations.exceptions.LicornRuntimeException'>[0;0m
>>> [01;32mCall trace[0;0m:
  File "../interfaces/cli/del.py", line 232, in <module>
    delete_group()
  File "../interfaces/cli/del.py", line 133, in delete_group
    opts.gid)
  File "/usr/lib/python2.6/dist-packages/licorn/core/groups.py", line 482, in DeleteGroup
    gid = self.name_to_gid(name)
  File "/usr/lib/python2.6/dist-packages/licorn/core/groups.py", line 1306, in name_to_gid
    "The group '%s' doesn't exist." % name)

